Workbook
Name RMSE: _xlfn.LAMBDA(_xlpm.a,_xlpm.b,_xlpm.x,_xlpm.y,SQRT(SUM(((_xlpm.a*_xlpm.x+_xlpm.b)-_xlpm.y)^2)/COUNT(_xlpm.y)))

Sheet 係数の検定
A1: 中古車データ（架空データ）
A3: メーカー | B3: 名称 | C3: タイプ | D3: 年式 | E3: 走行（km） | F3: 排気量（cc） | G3: ミッション | H3: 車検 | I3: 本体価格（万円） | L3: 排気量 | M3: 走行 | N3: 年式 | O3: 定数項
A4: スバル | B4: レガシィ | C4: セダン | D4: 2016 | E4: 55000 | F4: 2500 | G4: CVT | H4: 令和2年4月 | I4: 160 | K4: 係数
A5: マツダ | B5: CX-5 | C5: SUV | D5: 2018 | E5: 40000 | F5: 2000 | G5: AT | H5: 令和3年1月 | I5: 170 | K5: 標準誤差
A6: スズキ | B6: アルト | C6: コンパクト | D6: 2019 | E6: 20000 | F6: 660 | G6: CVT | H6: 令和3年1月 | I6: 80 | K6: R2｜yの標準誤差
A7: 日産 | B7: ティアナ | C7: セダン | D7: 2016 | E7: 55000 | F7: 2500 | G7: CVT | H7: 令和2年8月 | I7: 160 | K7: F｜自由度
A8: マツダ | B8: CX-9 | C8: SUV | D8: 2017 | E8: 35000 | F8: 2500 | G8: AT | H8: 令和2年11月 | I8: 200 | K8: 回帰｜誤差の二乗和
A9: トヨタ | B9: ハイエース | C9: バン | D9: 2019 | E9: 40000 | F9: 2500 | G9: AT | H9: 車検切れ | I9: 80
A10: アルファロメオ | B10: ジュリアスプリント | C10: クーペ | D10: 1962 | E10: 70000 | F10: 1600 | G10: MT | H10: 令和2年12月 | I10: 550 | K10: 回帰式の当てはまり | L10: =_xlfn.F.DIST.RT(L7,3,M7) -> #NUM!
A11: ポルシェ | B11: 911 | C11: スポーツカー | D11: 2020 | E11: 15000 | F11: 3000 | G11: AT | H11: 令和3年5月 | I11: 450
A12: トヨタ | B12: パッソ | C12: コンパクト | D12: 2017 | E12: 30000 | F12: 1000 | G12: CVT | H12: 令和2年11月 | I12: 85 | K12: 係数の有効性 | L12: 排気量 | M12: 走行 | N12: 年式
A13: マツダ | B13: ロードスター | C13: スポーツカー | D13: 2017 | E13: 40000 | F13: 2000 | G13: MT | H13: 令和2年1月 | I13: 120 | K13: T
A14: スズキ | B14: バレーノ | C14: コンパクト | D14: 2016 | E14: 65000 | F14: 1400 | G14: MT | H14: 令和2年5月 | I14: 100 | K14: P
A15: テスラ | B15: モデル3 | C15: セダン | D15: 2019 | E15: 25000 | F15: 0 | H15: 令和3年1月 | I15: 300
A16: フォルクスワーゲン | B16: ティグアン | C16: SUV | D16: 2017 | E16: 50000 | F16: 2000 | G16: AT | H16: 令和2年8月 | I16: 240
A17: マツダ | B17: デミオ | C17: コンパクト | D17: 2015 | E17: 65000 | F17: 1300 | G17: MT | H17: 令和2年1月 | I17: 80
A18: トヨタ | B18: ヴィッツ | C18: ハッチバック | D18: 2014 | E18: 80000 | F18: 1000 | G18: CVT | H18: 車検切れ | I18: 28
A19: ホンダ | B19: フィット | C19: ハッチバック | D19: 2017 | E19: 55000 | F19: 1300 | G19: MT | H19: 令和2年8月 | I19: 120
A20: 日産 | B20: セントラ | C20: セダン | D20: 2017 | E20: 40000 | F20: 1600 | G20: CVT | H20: 令和2年11月 | I20: 120
A21: スズキ | B21: ソリオ | C21: ワゴン | D21: 2015 | E21: 70000 | F21: 1200 | G21: CVT | H21: 車検切れ | I21: 28
A22: スバル | B22: レヴォーグ | C22: ワゴン | D22: 2016 | E22: 50000 | F22: 1600 | G22: CVT | H22: 令和2年10月 | I22: 150
A23: ホンダ | B23: ライフ | C23: ワゴン | D23: 2018 | E23: 24000 | F23: 660 | G23: CVT | H23: 令和3年1月 | I23: 76
A24: トヨタ | B24: ヴォクシー | C24: ミニバン | D24: 2017 | E24: 60000 | F24: 2000 | G24: CVT | H24: 令和2年12月 | I24: 170
A25: ポルシェ | B25: 911 | C25: スポーツカー | D25: 1985 | E25: 80000 | F25: 3200 | G25: MT | H25: 令和2年8月 | I25: 300
A26: ホンダ | B26: インサイト | C26: ハイブリッド | D26: 2010 | E26: 120000 | F26: 1300 | G26: CVT | H26: 車検切れ | I26: 25
A27: 日産 | B27: ノート | C27: セダン | D27: 2016 | E27: 70000 | F27: 1600 | G27: CVT | H27: 令和2年5月 | I27: 100
A28: トヨタ | B28: ピクシスエポック | C28: コンパクト | D28: 2018 | E28: 24000 | F28: 660 | G28: CVT | H28: 令和2年12月 | I28: 75
A29: アウディ | B29: A4 | C29: セダン | D29: 2019 | E29: 28000 | F29: 2000 | G29: AT | H29: 令和3年1月 | I29: 270
A30: トヨタ | B30: プリウス | C30: ハイブリッド | D30: 2013 | E30: 90000 | F30: 1800 | G30: CVT | H30: 車検切れ | I30: 35
A31: ホンダ | B31: シャトル | C31: ハッチバック | D31: 2018 | E31: 40000 | F31: 1500 | G31: CVT | H31: 令和3年1月 | I31: 160
A32: 日産 | B32: フェアレディZ | C32: スポーツカー | D32: 2016 | E32: 60000 | F32: 3700 | G32: MT | H32: 令和2年12月 | I32: 250
A33: ホンダ | B33: N-WGN | C33: ワゴン | D33: 2018 | E33: 22000 | F33: 660 | G33: CVT | H33: 令和3年3月 | I33: 90
A34: BMW | B34: 5シリーズ | C34: セダン | D34: 2018 | E34: 36000 | F34: 2500 | G34: AT | H34: 令和3年6月 | I34: 290
A35: ホンダ | B35: フィットハイブリッド | C35: ハッチバック | D35: 2017 | E35: 48000 | F35: 1300 | G35: CVT | H35: 令和2年6月 | I35: 150
A36: ホンダ | B36: フィット | C36: ハッチバック | D36: 2008 | E36: 150000 | F36: 1300 | G36: CVT | H36: 車検切れ | I36: 30
A37: 日産 | B37: ムラーノ | C37: SUV | D37: 2019 | E37: 30000 | F37: 3500 | G37: CVT | H37: 令和3年4月 | I37: 220
... A53: ポルシェ | B53: カイエン | C53: SUV | D53: 2019 | E53: 22000 | F53: 3000 | G53: AT | H53: 令和3年2月 | I53: 380

Sheet 係数の検定 (作成例)
A1: 中古車データ（架空データ）
A3: メーカー | B3: 名称 | C3: タイプ | D3: 年式 | E3: 走行（km） | F3: 排気量（cc） | G3: ミッション | H3: 車検 | I3: 本体価格（万円） | L3: 排気量 | M3: 走行 | N3: 年式 | O3: 定数項
A4: スバル | B4: レガシィ | C4: セダン | D4: 2016 | E4: 55000 | F4: 2500 | G4: CVT | H4: 令和2年4月 | I4: 160 | K4: 係数 | L4: {=LINEST(I4:I53,D4:F53,TRUE,TRUE)} -> 0.06442329 | M4: -0.0019785046 | N4: -7.0003128 | O4: 14252.304
A5: マツダ | B5: CX-5 | C5: SUV | D5: 2018 | E5: 40000 | F5: 2000 | G5: AT | H5: 令和3年1月 | I5: 170 | K5: 標準誤差 | L5: 0.013096781 | M5: 0.00034299364 | N5: 1.228964 | O5: 2485.4773
A6: スズキ | B6: アルト | C6: コンパクト | D6: 2019 | E6: 20000 | F6: 660 | G6: CVT | H6: 令和3年1月 | I6: 80 | K6: R2｜yの標準誤差 | L6: 0.62903095 | M6: 72.482121 | N6: #N/A | O6: #N/A
A7: 日産 | B7: ティアナ | C7: セダン | D7: 2016 | E7: 55000 | F7: 2500 | G7: CVT | H7: 令和2年8月 | I7: 160 | K7: F｜自由度 | L7: 25.999854 | M7: 46 | N7: #N/A | O7: #N/A
A8: マツダ | B8: CX-9 | C8: SUV | D8: 2017 | E8: 35000 | F8: 2500 | G8: AT | H8: 令和2年11月 | I8: 200 | K8: 回帰｜誤差の二乗和 | L8: 409783.02 | M8: 241668.26 | N8: #N/A | O8: #N/A
A9: トヨタ | B9: ハイエース | C9: バン | D9: 2019 | E9: 40000 | F9: 2500 | G9: AT | H9: 車検切れ | I9: 80
A10: アルファロメオ | B10: ジュリアスプリント | C10: クーペ | D10: 1962 | E10: 70000 | F10: 1600 | G10: MT | H10: 令和2年12月 | I10: 550 | K10: 回帰式の当てはまり | L10: =_xlfn.F.DIST.RT(L7,3,M7) -> 5.4909154e-10
A11: ポルシェ | B11: 911 | C11: スポーツカー | D11: 2020 | E11: 15000 | F11: 3000 | G11: AT | H11: 令和3年5月 | I11: 450
A12: トヨタ | B12: パッソ | C12: コンパクト | D12: 2017 | E12: 30000 | F12: 1000 | G12: CVT | H12: 令和2年11月 | I12: 85 | K12: 係数の有効性 | L12: 排気量 | M12: 走行 | N12: 年式
A13: マツダ | B13: ロードスター | C13: スポーツカー | D13: 2017 | E13: 40000 | F13: 2000 | G13: MT | H13: 令和2年1月 | I13: 120 | K13: T | L13: {=L4:N4/L5:N5} -> 4.9190171 | M13: -5.7683421 | N13: -5.696109
A14: スズキ | B14: バレーノ | C14: コンパクト | D14: 2016 | E14: 65000 | F14: 1400 | G14: MT | H14: 令和2年5月 | I14: 100 | K14: P | L14: {=_xlfn.T.DIST.2T(ABS(_xlfn.ANCHORARRAY(L13)),M7)} -> 1.1529482e-05 | M14: 6.4330996e-07 | N14: 8.2456448e-07
A15: テスラ | B15: モデル3 | C15: セダン | D15: 2019 | E15: 25000 | F15: 0 | H15: 令和3年1月 | I15: 300
A16: フォルクスワーゲン | B16: ティグアン | C16: SUV | D16: 2017 | E16: 50000 | F16: 2000 | G16: AT | H16: 令和2年8月 | I16: 240 | K16: ボンフェローニの補正 | L16: {=_xlfn.ANCHORARRAY(L14)/3} -> 3.8431606e-06 | M16: 2.1443665e-07 | N16: 2.7485483e-07
A17: マツダ | B17: デミオ | C17: コンパクト | D17: 2015 | E17: 65000 | F17: 1300 | G17: MT | H17: 令和2年1月 | I17: 80
A18: トヨタ | B18: ヴィッツ | C18: ハッチバック | D18: 2014 | E18: 80000 | F18: 1000 | G18: CVT | H18: 車検切れ | I18: 28 | K18: 小さい順に並べ替え | L18: {=_xlfn.XLOOKUP(_xlfn.ANCHORARRAY(L19),_xlfn.ANCHORARRAY(L14),L3:N3,,0,1)} -> 走行 | M18: 年式 | N18: 排気量
A19: ホンダ | B19: フィット | C19: ハッチバック | D19: 2017 | E19: 55000 | F19: 1300 | G19: MT | H19: 令和2年8月 | I19: 120 | K19: P | L19: {=_xlfn._xlws.SORT(_xlfn.ANCHORARRAY(L14),,1,TRUE)} -> 6.4330996e-07 | M19: 8.2456448e-07 | N19: 1.1529482e-05
A20: 日産 | B20: セントラ | C20: セダン | D20: 2017 | E20: 40000 | F20: 1600 | G20: CVT | H20: 令和2年11月 | I20: 120 | K20: ホルムの補正 | L20: {=_xlfn.ANCHORARRAY(L19)/(COUNT(_xlfn.ANCHORARRAY(L19))-(COLUMN(_xlfn.ANCHORARRAY(L19))-COLUMN(L19)))} -> 2.1443665e-07 | M20: 4.1228224e-07 | N20: 1.1529482e-05
A21: スズキ | B21: ソリオ | C21: ワゴン | D21: 2015 | E21: 70000 | F21: 1200 | G21: CVT | H21: 車検切れ | I21: 28
A22: スバル | B22: レヴォーグ | C22: ワゴン | D22: 2016 | E22: 50000 | F22: 1600 | G22: CVT | H22: 令和2年10月 | I22: 150 | K22: 信頼区間 | L22: 排気量 | M22: 走行 | N22: 年式
A23: ホンダ | B23: ライフ | C23: ワゴン | D23: 2018 | E23: 24000 | F23: 660 | G23: CVT | H23: 令和3年1月 | I23: 76 | K23: 下限 | L23: {=L4:N4-_xlfn.T.INV.2T(0.05,M7)*L5:N5} -> 0.038060837 | M23: -0.002668915 | N23: -9.4740889
A24: トヨタ | B24: ヴォクシー | C24: ミニバン | D24: 2017 | E24: 60000 | F24: 2000 | G24: CVT | H24: 令和2年12月 | I24: 170 | K24: 上限 | L24: {=L4:N4+_xlfn.T.INV.2T(0.05,M7)*L5:N5} -> 0.090785742 | M24: -0.0012880943 | N24: -4.5265366
A25: ポルシェ | B25: 911 | C25: スポーツカー | D25: 1985 | E25: 80000 | F25: 3200 | G25: MT | H25: 令和2年8月 | I25: 300
A26: ホンダ | B26: インサイト | C26: ハイブリッド | D26: 2010 | E26: 120000 | F26: 1300 | G26: CVT | H26: 車検切れ | I26: 25
A27: 日産 | B27: ノート | C27: セダン | D27: 2016 | E27: 70000 | F27: 1600 | G27: CVT | H27: 令和2年5月 | I27: 100
A28: トヨタ | B28: ピクシスエポック | C28: コンパクト | D28: 2018 | E28: 24000 | F28: 660 | G28: CVT | H28: 令和2年12月 | I28: 75
A29: アウディ | B29: A4 | C29: セダン | D29: 2019 | E29: 28000 | F29: 2000 | G29: AT | H29: 令和3年1月 | I29: 270
A30: トヨタ | B30: プリウス | C30: ハイブリッド | D30: 2013 | E30: 90000 | F30: 1800 | G30: CVT | H30: 車検切れ | I30: 35
A31: ホンダ | B31: シャトル | C31: ハッチバック | D31: 2018 | E31: 40000 | F31: 1500 | G31: CVT | H31: 令和3年1月 | I31: 160
A32: 日産 | B32: フェアレディZ | C32: スポーツカー | D32: 2016 | E32: 60000 | F32: 3700 | G32: MT | H32: 令和2年12月 | I32: 250
A33: ホンダ | B33: N-WGN | C33: ワゴン | D33: 2018 | E33: 22000 | F33: 660 | G33: CVT | H33: 令和3年3月 | I33: 90
A34: BMW | B34: 5シリーズ | C34: セダン | D34: 2018 | E34: 36000 | F34: 2500 | G34: AT | H34: 令和3年6月 | I34: 290
A35: ホンダ | B35: フィットハイブリッド | C35: ハッチバック | D35: 2017 | E35: 48000 | F35: 1300 | G35: CVT | H35: 令和2年6月 | I35: 150
A36: ホンダ | B36: フィット | C36: ハッチバック | D36: 2008 | E36: 150000 | F36: 1300 | G36: CVT | H36: 車検切れ | I36: 30
A37: 日産 | B37: ムラーノ | C37: SUV | D37: 2019 | E37: 30000 | F37: 3500 | G37: CVT | H37: 令和3年4月 | I37: 220
... A53: ポルシェ | B53: カイエン | C53: SUV | D53: 2019 | E53: 22000 | F53: 3000 | G53: AT | H53: 令和3年2月 | I53: 380

Sheet 係数の検定 (標準化)
A1: 中古車データ（架空データ：標準化） | Q1: 基本統計量
A3: メーカー | B3: 名称 | C3: タイプ | D3: 年式 | E3: 走行（km） | F3: 排気量（cc） | G3: ミッション | H3: 車検 | I3: 本体価格（万円） | L3: 排気量 | M3: 走行 | N3: 年式 | O3: 定数項 | R3: 年式 | S3: 走行 | T3: 排気量
A4: スバル | B4: レガシィ | C4: セダン | D4: {=STANDARDIZE(係数の検定!D4:F53,R4:T4,R5:T5)} -> 0.1401932 | E4: 0.047702041 | F4: 0.929615 | G4: CVT | H4: 令和2年4月 | I4: 160 | K4: 係数 | L4: {=LINEST(I4:I53,D4:F53,TRUE,TRUE)} -> 50.645203 | M4: -64.703043 | N4: -63.914657 | O4: 156.88 | Q4: 平均 | R4: =AVERAGE(係数の検定!D4:D53) -> 2014.72 | S4: =AVERAGE(係数の検定!E4:E53) -> 53440 | T4: =AVERAGE(係数の検定!F4:F53) -> 1769.2
A5: マツダ | B5: CX-5 | C5: SUV | D5: 0.35924507 | E5: -0.41097143 | F5: 0.29358941 | G5: AT | H5: 令和3年1月 | I5: 170 | K5: 標準誤差 | L5: 10.295797 | M5: 11.216922 | N5: 11.220757 | O5: 10.25052 | Q5: 標準偏差 | R5: =_xlfn.STDEV.P(係数の検定!D4:D53) -> 9.1302574 | S5: =_xlfn.STDEV.P(係数の検定!E4:E53) -> 32703.003 | T5: =_xlfn.STDEV.P(係数の検定!F4:F53) -> 786.1319
A6: スズキ | B6: アルト | C6: コンパクト | D6: 0.46877101 | E6: -1.0225361 | F6: -1.4109592 | G6: CVT | H6: 令和3年1月 | I6: 80 | K6: R2｜yの標準誤差 | L6: 0.62903095 | M6: 72.482121 | N6: #N/A | O6: #N/A
A7: 日産 | B7: ティアナ | C7: セダン | D7: 0.1401932 | E7: 0.047702041 | F7: 0.929615 | G7: CVT | H7: 令和2年8月 | I7: 160 | K7: F｜自由度 | L7: 25.999854 | M7: 46 | N7: #N/A | O7: #N/A | Q7: ◆ 標準化の方法
A8: マツダ | B8: CX-9 | C8: SUV | D8: 0.24971914 | E8: -0.56386259 | F8: 0.929615 | G8: AT | H8: 令和2年11月 | I8: 200 | K8: 回帰｜誤差の二乗和 | L8: 409783.02 | M8: 241668.26 | N8: #N/A | O8: #N/A | Q8: ・元のデータは「係数の検定」ワークシートにあるのでそれを使う
A9: トヨタ | B9: ハイエース | C9: バン | D9: 0.46877101 | E9: -0.41097143 | F9: 0.929615 | G9: AT | H9: 車検切れ | I9: 80 | Q9: ・標準化の計算方法は（各データ-平均）/標準偏差
A10: アルファロメオ | B10: ジュリアスプリント | C10: クーペ | D10: -5.7742074 | E10: 0.50637552 | F10: -0.21523106 | G10: MT | H10: 令和2年12月 | I10: 550 | K10: 回帰式の当てはまり | L10: =_xlfn.F.DIST.RT(L7,3,M7) -> 5.4909154e-10 | Q10: ・上の式で計算してもいいがSTANDARDIZE関数が使える
A11: ポルシェ | B11: 911 | C11: スポーツカー | D11: 0.57829695 | E11: -1.1754272 | F11: 1.5656406 | G11: AT | H11: 令和3年5月 | I11: 450
A12: トヨタ | B12: パッソ | C12: コンパクト | D12: 0.24971914 | E12: -0.71675375 | F12: -0.97846176 | G12: CVT | H12: 令和2年11月 | I12: 85 | K12: 係数の有効性 | L12: 排気量 | M12: 走行 | N12: 年式 | Q12: ◆ 手順
A13: マツダ | B13: ロードスター | C13: スポーツカー | D13: 0.24971914 | E13: -0.41097143 | F13: 0.29358941 | G13: MT | H13: 令和2年1月 | I13: 120 | K13: T | L13: {=L4:N4/L5:N5} -> 4.9190171 | M13: -5.7683421 | N13: -5.696109 | Q13: ① セルR4に「=AVERAGE(係数の検定!D4:D53)」と入力する
A14: スズキ | B14: バレーノ | C14: コンパクト | D14: 0.1401932 | E14: 0.35348436 | F14: -0.46964129 | G14: MT | H14: 令和2年5月 | I14: 100 | K14: P | L14: {=_xlfn.T.DIST.2T(ABS(_xlfn.ANCHORARRAY(L13)),M7)} -> 1.1529482e-05 | M14: 6.4330996e-07 | N14: 8.2456448e-07 | Q14: ② セルR4をセルT4までコピーする
A15: テスラ | B15: モデル3 | C15: セダン | D15: 0.46877101 | E15: -0.86964491 | F15: -2.2505129 | H15: 令和3年1月 | I15: 300 | Q15: ③ セルR5に「=STDEV.P(係数の検定!D4:D53)」と入力する
A16: フォルクスワーゲン | B16: ティグアン | C16: SUV | D16: 0.24971914 | E16: -0.10518912 | F16: 0.29358941 | G16: AT | H16: 令和2年8月 | I16: 240 | K16: ボンフェローニの補正 | L16: {=_xlfn.ANCHORARRAY(L14)/3} -> 3.8431606e-06 | M16: 2.1443665e-07 | N16: 2.7485483e-07 | Q16: ④ セルR5をセルT5までコピーする
A17: マツダ | B17: デミオ | C17: コンパクト | D17: 0.030667262 | E17: 0.35348436 | F17: -0.59684641 | G17: MT | H17: 令和2年1月 | I17: 80 | Q17: ⑤ セルD4に「=STANDARDIZE(係数の検定!D4:F53,R4:T4,R5:T5)」と入力する
A18: トヨタ | B18: ヴィッツ | C18: ハッチバック | D18: -0.078858675 | E18: 0.81215783 | F18: -0.97846176 | G18: CVT | H18: 車検切れ | I18: 28 | K18: 小さい順に並べ替え | L18: {=_xlfn.XLOOKUP(_xlfn.ANCHORARRAY(L19),_xlfn.ANCHORARRAY(L14),L3:N3,,0,1)} -> 走行 | M18: 年式 | N18: 排気量
A19: ホンダ | B19: フィット | C19: ハッチバック | D19: 0.24971914 | E19: 0.047702041 | F19: -0.59684641 | G19: MT | H19: 令和2年8月 | I19: 120 | K19: P | L19: {=_xlfn._xlws.SORT(_xlfn.ANCHORARRAY(L14),,1,TRUE)} -> 6.4330996e-07 | M19: 8.2456448e-07 | N19: 1.1529482e-05
A20: 日産 | B20: セントラ | C20: セダン | D20: 0.24971914 | E20: -0.41097143 | F20: -0.21523106 | G20: CVT | H20: 令和2年11月 | I20: 120 | K20: ホルムの補正 | L20: {=_xlfn.ANCHORARRAY(L19)/(COUNT(_xlfn.ANCHORARRAY(L19))-(COLUMN(_xlfn.ANCHORARRAY(L19))-COLUMN(L19)))} -> 2.1443665e-07 | M20: 4.1228224e-07 | N20: 1.1529482e-05
A21: スズキ | B21: ソリオ | C21: ワゴン | D21: 0.030667262 | E21: 0.50637552 | F21: -0.72405153 | G21: CVT | H21: 車検切れ | I21: 28
A22: スバル | B22: レヴォーグ | C22: ワゴン | D22: 0.1401932 | E22: -0.10518912 | F22: -0.21523106 | G22: CVT | H22: 令和2年10月 | I22: 150 | K22: 信頼区間 | L22: 排気量 | M22: 走行 | N22: 年式
A23: ホンダ | B23: ライフ | C23: ワゴン | D23: 0.35924507 | E23: -0.90022314 | F23: -1.4109592 | G23: CVT | H23: 令和3年1月 | I23: 76 | K23: 下限 | L23: {=L4:N4-_xlfn.T.INV.2T(0.05,M7)*L5:N5} -> 29.920838 | M23: -87.281536 | N23: -86.50087
A24: トヨタ | B24: ヴォクシー | C24: ミニバン | D24: 0.24971914 | E24: 0.2005932 | F24: 0.29358941 | G24: CVT | H24: 令和2年12月 | I24: 170 | K24: 上限 | L24: {=L4:N4+_xlfn.T.INV.2T(0.05,M7)*L5:N5} -> 71.369568 | M24: -42.12455 | N24: -41.328444
A25: ポルシェ | B25: 911 | C25: スポーツカー | D25: -3.2551109 | E25: 0.81215783 | F25: 1.8200508 | G25: MT | H25: 令和2年8月 | I25: 300
A26: ホンダ | B26: インサイト | C26: ハイブリッド | D26: -0.51696242 | E26: 2.0352871 | F26: -0.59684641 | G26: CVT | H26: 車検切れ | I26: 25
A27: 日産 | B27: ノート | C27: セダン | D27: 0.1401932 | E27: 0.50637552 | F27: -0.21523106 | G27: CVT | H27: 令和2年5月 | I27: 100
A28: トヨタ | B28: ピクシスエポック | C28: コンパクト | D28: 0.35924507 | E28: -0.90022314 | F28: -1.4109592 | G28: CVT | H28: 令和2年12月 | I28: 75
A29: アウディ | B29: A4 | C29: セダン | D29: 0.46877101 | E29: -0.77791021 | F29: 0.29358941 | G29: AT | H29: 令和3年1月 | I29: 270
A30: トヨタ | B30: プリウス | C30: ハイブリッド | D30: -0.18838461 | E30: 1.1179402 | F30: 0.039179176 | G30: CVT | H30: 車検切れ | I30: 35
A31: ホンダ | B31: シャトル | C31: ハッチバック | D31: 0.35924507 | E31: -0.41097143 | F31: -0.34243618 | G31: CVT | H31: 令和3年1月 | I31: 160
A32: 日産 | B32: フェアレディZ | C32: スポーツカー | D32: 0.1401932 | E32: 0.2005932 | F32: 2.4560764 | G32: MT | H32: 令和2年12月 | I32: 250
A33: ホンダ | B33: N-WGN | C33: ワゴン | D33: 0.35924507 | E33: -0.9613796 | F33: -1.4109592 | G33: CVT | H33: 令和3年3月 | I33: 90
A34: BMW | B34: 5シリーズ | C34: セダン | D34: 0.35924507 | E34: -0.53328436 | F34: 0.929615 | G34: AT | H34: 令和3年6月 | I34: 290
A35: ホンダ | B35: フィットハイブリッド | C35: ハッチバック | D35: 0.24971914 | E35: -0.16634558 | F35: -0.59684641 | G35: CVT | H35: 令和2年6月 | I35: 150
A36: ホンダ | B36: フィット | C36: ハッチバック | D36: -0.7360143 | E36: 2.9526341 | F36: -0.59684641 | G36: CVT | H36: 車検切れ | I36: 30
A37: 日産 | B37: ムラーノ | C37: SUV | D37: 0.46877101 | E37: -0.71675375 | F37: 2.2016662 | G37: CVT | H37: 令和3年4月 | I37: 220
... A53: ポルシェ | B53: カイエン | C53: SUV | D53: 0.46877101 | E53: -0.9613796 | F53: 1.5656406 | G53: AT | H53: 令和3年2月 | I53: 380

Sheet 多重共線性
A1: 中古車データ（架空データ） | K1: 多重共線性
A3: メーカー | B3: 名称 | C3: タイプ | D3: 年式 | E3: 走行（km） | F3: 排気量（cc） | G3: ミッション | H3: 車検 | I3: 本体価格（万円） | K3: 相関行列 | L3: 年式 | M3: 走行 | N3: 排気量 | P3: ◆ 相関行列を求める手順
A4: スバル | B4: レガシィ | C4: セダン | D4: 2016 | E4: 55000 | F4: 2500 | G4: CVT | H4: 令和2年4月 | I4: 160 | K4: 年式 | L4: 1 | M4: =CORREL(D4:D53,E4:E53) -> -0.40000692 | N4: =CORREL(D4:D53,F4:F53) -> -0.054589937 | P4: ① 対角成分には1を入力しておく
A5: マツダ | B5: CX-5 | C5: SUV | D5: 2018 | E5: 40000 | F5: 2000 | G5: AT | H5: 令和3年1月 | I5: 170 | K5: 走行 | L5: =M4 -> -0.40000692 | M5: 1 | N5: =CORREL(E4:E53,F4:F53) -> -0.047938623 | P5: ② セルM4に「=CORREL(D4:D53,E4:E53)」と入力する
A6: スズキ | B6: アルト | C6: コンパクト | D6: 2019 | E6: 20000 | F6: 660 | G6: CVT | H6: 令和3年1月 | I6: 80 | K6: 排気量 | L6: =N4 -> -0.054589937 | M6: =N5 -> -0.047938623 | N6: 1 | P6: ③ セルN4に「=CORREL(D4:D53,F4:F53)」と入力する
A7: 日産 | B7: ティアナ | C7: セダン | D7: 2016 | E7: 55000 | F7: 2500 | G7: CVT | H7: 令和2年8月 | I7: 160 | P7: ④ セルN5に「=CORREL(E4:E53,F4:F53)」と入力する
A8: マツダ | B8: CX-9 | C8: SUV | D8: 2017 | E8: 35000 | F8: 2500 | G8: AT | H8: 令和2年11月 | I8: 200 | K8: 逆行列 | L8: 年式 | M8: 走行 | N8: 排気量 | P8: ⑤ セルL5に「=M4」と入力する
A9: トヨタ | B9: ハイエース | C9: バン | D9: 2019 | E9: 40000 | F9: 2500 | G9: AT | H9: 車検切れ | I9: 80 | K9: 年式 | L9: {=MINVERSE(L4:N6)} -> 1.1982641 | M9: 0.48356104 | N9: 0.088594413 | P9: ⑥ セルL6に「=N4」と入力する
A10: アルファロメオ | B10: ジュリアスプリント | C10: クーペ | D10: 1962 | E10: 70000 | F10: 1600 | G10: MT | H10: 令和2年12月 | I10: 550 | K10: 走行 | L10: 0.48356104 | M10: 1.1974451 | N10: 0.083801435 | P10: ⑦ セルM6に「=N5」と入力する
A11: ポルシェ | B11: 911 | C11: スポーツカー | D11: 2020 | E11: 15000 | F11: 3000 | G11: AT | H11: 令和3年5月 | I11: 450 | K11: 排気量 | L11: 0.088594413 | M11: 0.083801435 | N11: 1.0088537
A12: トヨタ | B12: パッソ | C12: コンパクト | D12: 2017 | E12: 30000 | F12: 1000 | G12: CVT | H12: 令和2年11月 | I12: 85 | P12: ◆ 逆行列を求める手順
A13: マツダ | B13: ロードスター | C13: スポーツカー | D13: 2017 | E13: 40000 | F13: 2000 | G13: MT | H13: 令和2年1月 | I13: 120 | P13: ①セルL9に「=MINVERSE(L4:N6)」と入力する
A14: スズキ | B14: バレーノ | C14: コンパクト | D14: 2016 | E14: 65000 | F14: 1400 | G14: MT | H14: 令和2年5月 | I14: 100
A15: テスラ | B15: モデル3 | C15: セダン | D15: 2019 | E15: 25000 | F15: 0 | H15: 令和3年1月 | I15: 300 | P15: ◆ VIF（分散拡大係数）
A16: フォルクスワーゲン | B16: ティグアン | C16: SUV | D16: 2017 | E16: 50000 | F16: 2000 | G16: AT | H16: 令和2年8月 | I16: 240 | P16: 逆行列の対角成分がVIFの値（太字の値）
A17: マツダ | B17: デミオ | C17: コンパクト | D17: 2015 | E17: 65000 | F17: 1300 | G17: MT | H17: 令和2年1月 | I17: 80 | P17: VIFの値が5～10を超えると多重共線性が見られる
A18: トヨタ | B18: ヴィッツ | C18: ハッチバック | D18: 2014 | E18: 80000 | F18: 1000 | G18: CVT | H18: 車検切れ | I18: 28
A19: ホンダ | B19: フィット | C19: ハッチバック | D19: 2017 | E19: 55000 | F19: 1300 | G19: MT | H19: 令和2年8月 | I19: 120
A20: 日産 | B20: セントラ | C20: セダン | D20: 2017 | E20: 40000 | F20: 1600 | G20: CVT | H20: 令和2年11月 | I20: 120
A21: スズキ | B21: ソリオ | C21: ワゴン | D21: 2015 | E21: 70000 | F21: 1200 | G21: CVT | H21: 車検切れ | I21: 28
A22: スバル | B22: レヴォーグ | C22: ワゴン | D22: 2016 | E22: 50000 | F22: 1600 | G22: CVT | H22: 令和2年10月 | I22: 150
A23: ホンダ | B23: ライフ | C23: ワゴン | D23: 2018 | E23: 24000 | F23: 660 | G23: CVT | H23: 令和3年1月 | I23: 76
A24: トヨタ | B24: ヴォクシー | C24: ミニバン | D24: 2017 | E24: 60000 | F24: 2000 | G24: CVT | H24: 令和2年12月 | I24: 170
A25: ポルシェ | B25: 911 | C25: スポーツカー | D25: 1985 | E25: 80000 | F25: 3200 | G25: MT | H25: 令和2年8月 | I25: 300
A26: ホンダ | B26: インサイト | C26: ハイブリッド | D26: 2010 | E26: 120000 | F26: 1300 | G26: CVT | H26: 車検切れ | I26: 25
A27: 日産 | B27: ノート | C27: セダン | D27: 2016 | E27: 70000 | F27: 1600 | G27: CVT | H27: 令和2年5月 | I27: 100
A28: トヨタ | B28: ピクシスエポック | C28: コンパクト | D28: 2018 | E28: 24000 | F28: 660 | G28: CVT | H28: 令和2年12月 | I28: 75
A29: アウディ | B29: A4 | C29: セダン | D29: 2019 | E29: 28000 | F29: 2000 | G29: AT | H29: 令和3年1月 | I29: 270
A30: トヨタ | B30: プリウス | C30: ハイブリッド | D30: 2013 | E30: 90000 | F30: 1800 | G30: CVT | H30: 車検切れ | I30: 35
A31: ホンダ | B31: シャトル | C31: ハッチバック | D31: 2018 | E31: 40000 | F31: 1500 | G31: CVT | H31: 令和3年1月 | I31: 160
A32: 日産 | B32: フェアレディZ | C32: スポーツカー | D32: 2016 | E32: 60000 | F32: 3700 | G32: MT | H32: 令和2年12月 | I32: 250
A33: ホンダ | B33: N-WGN | C33: ワゴン | D33: 2018 | E33: 22000 | F33: 660 | G33: CVT | H33: 令和3年3月 | I33: 90
A34: BMW | B34: 5シリーズ | C34: セダン | D34: 2018 | E34: 36000 | F34: 2500 | G34: AT | H34: 令和3年6月 | I34: 290
A35: ホンダ | B35: フィットハイブリッド | C35: ハッチバック | D35: 2017 | E35: 48000 | F35: 1300 | G35: CVT | H35: 令和2年6月 | I35: 150
A36: ホンダ | B36: フィット | C36: ハッチバック | D36: 2008 | E36: 150000 | F36: 1300 | G36: CVT | H36: 車検切れ | I36: 30
A37: 日産 | B37: ムラーノ | C37: SUV | D37: 2019 | E37: 30000 | F37: 3500 | G37: CVT | H37: 令和3年4月 | I37: 220
... A53: ポルシェ | B53: カイエン | C53: SUV | D53: 2019 | E53: 22000 | F53: 3000 | G53: AT | H53: 令和3年2月 | I53: 380

Sheet 標準誤差
A1: 中古車データ（架空データ） | R1: ◆ LINEST関数を使わずに標準誤差を求める方法 | T1: ◆ 計算例
A3: メーカー | B3: 名称 | C3: タイプ | D3: 年式 | E3: 走行（km） | F3: 排気量（cc） | H3: ミッション | I3: 車検 | J3: 本体価格（万円） | M3: 排気量 | N3: 走行 | O3: 年式 | P3: 定数項 | R3: ● 説明変数をX、目的変数をyとして、まず係数と定数項を求める | U3: A
A4: スバル | B4: レガシィ | C4: セダン | D4: 2016 | E4: 55000 | F4: 2500 | G4: 1 | H4: CVT | I4: 令和2年4月 | J4: 160 | L4: 係数 | M4: {=LINEST(J4:J53,D4:F53,TRUE,TRUE)} -> 0.06442329 | N4: -0.0019785046 | O4: -7.0003128 | P4: 14252.304 | R4: ・この例ではXはセルD4:F53、yはセルJ4:J53 | T4: 年式 | U4: {=MMULT(MMULT(MINVERSE(MMULT(TRANSPOSE(D4:G53),D4:G53)),TRANSPOSE(D4:G53)),J4:J53)} -> -7.0003128
A5: マツダ | B5: CX-5 | C5: SUV | D5: 2018 | E5: 40000 | F5: 2000 | G5: 1 | H5: AT | I5: 令和3年1月 | J5: 170 | L5: 標準誤差 | M5: 0.013096781 | N5: 0.00034299364 | O5: 1.228964 | P5: 2485.4773 | R5: ・係数と定数項は以下の式で求められる | T5: 走行 | U5: -0.0019785046
A6: スズキ | B6: アルト | C6: コンパクト | D6: 2019 | E6: 20000 | F6: 660 | G6: 1 | H6: CVT | I6: 令和3年1月 | J6: 80 | L6: R2｜yの標準誤差 | M6: 0.62903095 | N6: 72.482121 | O6: #N/A | P6: #N/A | T6: 排気量 | U6: 0.06442329
A7: 日産 | B7: ティアナ | C7: セダン | D7: 2016 | E7: 55000 | F7: 2500 | G7: 1 | H7: CVT | I7: 令和2年8月 | J7: 160 | L7: F｜自由度 | M7: 25.999854 | N7: 46 | O7: #N/A | P7: #N/A | T7: 定数項 | U7: 14252.304
A8: マツダ | B8: CX-9 | C8: SUV | D8: 2017 | E8: 35000 | F8: 2500 | G8: 1 | H8: AT | I8: 令和2年11月 | J8: 200 | L8: 回帰｜誤差の二乗和 | M8: 409783.02 | N8: 241668.26 | O8: #N/A | P8: #N/A | R8: ここで、Aは係数と定数項のベクトル
A9: トヨタ | B9: ハイエース | C9: バン | D9: 2019 | E9: 40000 | F9: 2500 | G9: 1 | H9: AT | I9: 車検切れ | J9: 80 | R9: 上付きのTは転置行列、-1は逆行列を表す
A10: アルファロメオ | B10: ジュリアスプリント | C10: クーペ | D10: 1962 | E10: 70000 | F10: 1600 | G10: 1 | H10: MT | I10: 令和2年12月 | J10: 550 | L10: 回帰式の当てはまり | M10: =_xlfn.F.DIST.RT(M7,3,N7) -> 5.4909154e-10 | R10: 転置行列はTRANSPOSE関数で、逆行列はMINVERS関数で求められる
A11: ポルシェ | B11: 911 | C11: スポーツカー | D11: 2020 | E11: 15000 | F11: 3000 | G11: 1 | H11: AT | I11: 令和3年5月 | J11: 450 | R11: 行列の積はMMULT関数で求められる
A12: トヨタ | B12: パッソ | C12: コンパクト | D12: 2017 | E12: 30000 | F12: 1000 | G12: 1 | H12: CVT | I12: 令和2年11月 | J12: 85 | L12: 係数の有効性 | M12: 排気量 | N12: 走行 | O12: 年式 | R12: セルU4～U7が上の結果
A13: マツダ | B13: ロードスター | C13: スポーツカー | D13: 2017 | E13: 40000 | F13: 2000 | G13: 1 | H13: MT | I13: 令和2年1月 | J13: 120 | L13: T | M13: {=M4:O4/M5:O5} -> 4.9190171 | N13: -5.7683421 | O13: -5.696109 | R13: ・ここまではLINEST関数でも求められる（順序は異なる）
A14: スズキ | B14: バレーノ | C14: コンパクト | D14: 2016 | E14: 65000 | F14: 1400 | G14: 1 | H14: MT | I14: 令和2年5月 | J14: 100 | L14: P | M14: {=_xlfn.T.DIST.2T(ABS(_xlfn.ANCHORARRAY(M13)),N7)} -> 1.1529482e-05 | N14: 6.4330996e-07 | O14: 8.2456448e-07
A15: テスラ | B15: モデル3 | C15: セダン | D15: 2019 | E15: 25000 | F15: 0 | G15: 1 | I15: 令和3年1月 | J15: 300 | R15: ● yの誤差分散を求める | T15: yの誤差分散 | U15: {=SUMSQ(J4:J53-MMULT(D4:G53,_xlfn.ANCHORARRAY(U4)))/(50-3-1)} -> 5253.6579 | V15: ←このルートがセルN6の値
A16: フォルクスワーゲン | B16: ティグアン | C16: SUV | D16: 2017 | E16: 50000 | F16: 2000 | G16: 1 | H16: AT | I16: 令和2年8月 | J16: 240 | R16: ・以下の式で求められる
A17: マツダ | B17: デミオ | C17: コンパクト | D17: 2015 | E17: 65000 | F17: 1300 | G17: 1 | H17: MT | I17: 令和2年1月 | J17: 80
A18: トヨタ | B18: ヴィッツ | C18: ハッチバック | D18: 2014 | E18: 80000 | F18: 1000 | G18: 1 | H18: CVT | I18: 車検切れ | J18: 28
A19: ホンダ | B19: フィット | C19: ハッチバック | D19: 2017 | E19: 55000 | F19: 1300 | G19: 1 | H19: MT | I19: 令和2年8月 | J19: 120
A20: 日産 | B20: セントラ | C20: セダン | D20: 2017 | E20: 40000 | F20: 1600 | G20: 1 | H20: CVT | I20: 令和2年11月 | J20: 120 | R20: ここでは、サンプルサイズn=50、説明変数の個数k=3
A21: スズキ | B21: ソリオ | C21: ワゴン | D21: 2015 | E21: 70000 | F21: 1200 | G21: 1 | H21: CVT | I21: 車検切れ | J21: 28 | R21: セルU15が上の結果
A22: スバル | B22: レヴォーグ | C22: ワゴン | D22: 2016 | E22: 50000 | F22: 1600 | G22: 1 | H22: CVT | I22: 令和2年10月 | J22: 150 | R22: ・これはLINEST関数で求めたyの標準誤差（セルN6）の二乗
A23: ホンダ | B23: ライフ | C23: ワゴン | D23: 2018 | E23: 24000 | F23: 660 | G23: 1 | H23: CVT | I23: 令和3年1月 | J23: 76
A24: トヨタ | B24: ヴォクシー | C24: ミニバン | D24: 2017 | E24: 60000 | F24: 2000 | G24: 1 | H24: CVT | I24: 令和2年12月 | J24: 170 | R24: ● 分散共分散行列とyの誤差分散の積のルートを求める | T24: 年式 | U24: 走行 | V24: 排気量 | W24: 定数項
A25: ポルシェ | B25: 911 | C25: スポーツカー | D25: 1985 | E25: 80000 | F25: 3200 | G25: 1 | H25: MT | I25: 令和2年8月 | J25: 300 | T25: {=SQRT(MINVERSE(MMULT(TRANSPOSE(D4:G53),D4:G53))*U15)} -> 1.228964 | U25: 0.013044764 | V25: 0.036013045 | W25: #NUM!
A26: ホンダ | B26: インサイト | C26: ハイブリッド | D26: 2010 | E26: 120000 | F26: 1300 | G26: 1 | H26: CVT | I26: 車検切れ | J26: 25 | T26: 0.013044764 | U26: 0.00034299364 | V26: 0.00058523473 | W26: #NUM!
A27: 日産 | B27: ノート | C27: セダン | D27: 2016 | E27: 70000 | F27: 1600 | G27: 1 | H27: CVT | I27: 令和2年5月 | J27: 100 | T27: 0.036013045 | U27: 0.00058523473 | V27: 0.013096781 | W27: #NUM!
A28: トヨタ | B28: ピクシスエポック | C28: コンパクト | D28: 2018 | E28: 24000 | F28: 660 | G28: 1 | H28: CVT | I28: 令和2年12月 | J28: 75 | R28: セルT25～W28が上の結果 | T28: #NUM! | U28: #NUM! | V28: #NUM! | W28: 2485.4773
A29: アウディ | B29: A4 | C29: セダン | D29: 2019 | E29: 28000 | F29: 2000 | G29: 1 | H29: AT | I29: 令和3年1月 | J29: 270 | R29: その対角成分が標準誤差（順序は異なるがLINEST関数の標準誤差と等しくなっている）
A30: トヨタ | B30: プリウス | C30: ハイブリッド | D30: 2013 | E30: 90000 | F30: 1800 | G30: 1 | H30: CVT | I30: 車検切れ | J30: 35
A31: ホンダ | B31: シャトル | C31: ハッチバック | D31: 2018 | E31: 40000 | F31: 1500 | G31: 1 | H31: CVT | I31: 令和3年1月 | J31: 160
A32: 日産 | B32: フェアレディZ | C32: スポーツカー | D32: 2016 | E32: 60000 | F32: 3700 | G32: 1 | H32: MT | I32: 令和2年12月 | J32: 250
A33: ホンダ | B33: N-WGN | C33: ワゴン | D33: 2018 | E33: 22000 | F33: 660 | G33: 1 | H33: CVT | I33: 令和3年3月 | J33: 90
A34: BMW | B34: 5シリーズ | C34: セダン | D34: 2018 | E34: 36000 | F34: 2500 | G34: 1 | H34: AT | I34: 令和3年6月 | J34: 290
A35: ホンダ | B35: フィットハイブリッド | C35: ハッチバック | D35: 2017 | E35: 48000 | F35: 1300 | G35: 1 | H35: CVT | I35: 令和2年6月 | J35: 150
A36: ホンダ | B36: フィット | C36: ハッチバック | D36: 2008 | E36: 150000 | F36: 1300 | G36: 1 | H36: CVT | I36: 車検切れ | J36: 30
A37: 日産 | B37: ムラーノ | C37: SUV | D37: 2019 | E37: 30000 | F37: 3500 | G37: 1 | H37: CVT | I37: 令和3年4月 | J37: 220
A38: マツダ | B38: MX-5 | C38: スポーツカー | D38: 2017 | E38: 40000 | F38: 2000 | G38: 1 | H38: MT | I38: 令和2年1月 | J38: 120
A39: 日産 | B39: セレナ | C39: ミニバン | D39: 2016 | E39: 60000 | F39: 2500 | G39: 1 | H39: CVT | I39: 令和2年7月 | J39: 150
A40: ダイハツ | B40: ムーヴキャンバス | C40: ワゴン | D40: 2019 | E40: 18000 | F40: 660 | G40: 1 | H40: CVT | I40: 令和3年6月 | J40: 80
A41: 日産 | B41: ノート | C41: セダン | D41: 2016 | E41: 70000 | F41: 1600 | G41: 1 | H41: CVT | I41: 令和2年5月 | J41: 100
...
